{
  "comments": [
    {
      "unresolved": true,
      "key": {
        "uuid": "72c8c0bc_57e415a4",
        "filename": "ibm_vpd_app.cpp",
        "patchSetId": 9
      },
      "lineNbr": 381,
      "author": {
        "id": 1000522
      },
      "writtenOn": "2022-01-21T18:32:04Z",
      "side": 1,
      "message": "I am not 100% sure, still would like to know,\nwhat if the call is made from line 1440 and an exception is thrown by call method? Will that be caught in the next catch block or will it go uncaught and that is what we are expecting?",
      "revId": "87a4a2d83d89429c0a3963436aac76c083d83c8e",
      "serverId": "adbd0a64-1f21-4d83-b585-671fe73cb6e4"
    },
    {
      "unresolved": true,
      "key": {
        "uuid": "396d26e9_011f5819",
        "filename": "ibm_vpd_app.cpp",
        "patchSetId": 9
      },
      "lineNbr": 392,
      "author": {
        "id": 1000522
      },
      "writtenOn": "2022-01-21T18:32:04Z",
      "side": 1,
      "message": "Suggestion: \"call\" methohd will throw in all cases. So we can get rid of this check?\n\nhttps://gerrit.openbmc-project.xyz/c/openbmc/phosphor-virtual-sensor/+/38244",
      "range": {
        "startLine": 382,
        "startChar": 8,
        "endLine": 392,
        "endChar": 9
      },
      "revId": "87a4a2d83d89429c0a3963436aac76c083d83c8e",
      "serverId": "adbd0a64-1f21-4d83-b585-671fe73cb6e4"
    },
    {
      "unresolved": true,
      "key": {
        "uuid": "fe702349_5a430268",
        "filename": "ibm_vpd_app.cpp",
        "patchSetId": 9
      },
      "lineNbr": 434,
      "author": {
        "id": 1000386
      },
      "writtenOn": "2022-01-21T04:44:14Z",
      "side": 1,
      "message": "Not sure on severity, if discussed already then no issues, else please check",
      "range": {
        "startLine": 434,
        "startChar": 38,
        "endLine": 434,
        "endChar": 58
      },
      "revId": "87a4a2d83d89429c0a3963436aac76c083d83c8e",
      "serverId": "adbd0a64-1f21-4d83-b585-671fe73cb6e4"
    }
  ]
}