{
  "comments": [
    {
      "key": {
        "uuid": "fb55162f_020577ef",
        "filename": "ibm_vpd_app.cpp",
        "patchSetId": 5
      },
      "lineNbr": 1051,
      "author": {
        "id": 1000522
      },
      "writtenOn": "2021-04-21T06:01:26Z",
      "side": 1,
      "message": "Why we need this here? We are again throwing the exception which will be caught at line 1084 and will output the what().",
      "revId": "a683a8a5225215dbe3a8873a0382d74d7e0cd3c8",
      "serverId": "adbd0a64-1f21-4d83-b585-671fe73cb6e4",
      "unresolved": true
    },
    {
      "key": {
        "uuid": "9cb4b338_28600b17",
        "filename": "ibm_vpd_app.cpp",
        "patchSetId": 5
      },
      "lineNbr": 1051,
      "author": {
        "id": 1000362
      },
      "writtenOn": "2021-04-21T06:32:06Z",
      "side": 1,
      "message": "the cerr \u003c\u003c at line 1086 just prints the type of exception and not the display data which is thrown.",
      "parentUuid": "fb55162f_020577ef",
      "revId": "a683a8a5225215dbe3a8873a0382d74d7e0cd3c8",
      "serverId": "adbd0a64-1f21-4d83-b585-671fe73cb6e4",
      "unresolved": true
    },
    {
      "key": {
        "uuid": "fb965476_7b8dea12",
        "filename": "ibm_vpd_app.cpp",
        "patchSetId": 5
      },
      "lineNbr": 1051,
      "author": {
        "id": 1000522
      },
      "writtenOn": "2021-04-21T06:42:04Z",
      "side": 1,
      "message": "I did not get that. These are two identical lines, You are throwing the same exception again from here. Why the output of these lines will be different?",
      "parentUuid": "9cb4b338_28600b17",
      "revId": "a683a8a5225215dbe3a8873a0382d74d7e0cd3c8",
      "serverId": "adbd0a64-1f21-4d83-b585-671fe73cb6e4",
      "unresolved": true
    },
    {
      "key": {
        "uuid": "4b0ed54c_9e182ddb",
        "filename": "ibm_vpd_app.cpp",
        "patchSetId": 5
      },
      "lineNbr": 1051,
      "author": {
        "id": 1000362
      },
      "writtenOn": "2021-04-21T06:56:58Z",
      "side": 1,
      "message": "I think since the exception object e thrown at 1052 goes out of scope and destroyed at  line 1084. \ne.what() at line 1084 not able to extract the relevant exception data. so it just prints \"std::exception\"",
      "parentUuid": "fb965476_7b8dea12",
      "revId": "a683a8a5225215dbe3a8873a0382d74d7e0cd3c8",
      "serverId": "adbd0a64-1f21-4d83-b585-671fe73cb6e4",
      "unresolved": true
    }
  ]
}